[2023-08-21 18:50:19,939] (app.error) [ERROR] [197]: this is error log
NoneType: None
[2023-08-21 18:51:28,866] (app.error) [ERROR] [197]: this is error log
NoneType: None
[2023-08-21 18:51:44,782] (app.error) [ERROR] [198]: this is error log
NoneType: None
[2023-08-21 18:52:00,129] (app.error) [ERROR] [198]: this is error log
NoneType: None
[2023-08-21 18:52:13,150] (app.error) [ERROR] [197]: exception
NoneType: None
[2023-08-21 18:52:55,470] (app.error) [ERROR] [197]: exception
NoneType: None
[2023-08-21 18:53:06,733] (app.error) [ERROR] [197]: this is error log
NoneType: None
[2023-08-21 18:53:48,693] (app.error) [ERROR] [198]: this is error log
NoneType: None
[2023-08-21 18:54:55,165] (app.error) [ERROR] [197]: division by zero
Traceback (most recent call last):
  File "D:\workspace\ph-utils\tests\logger_utils.py", line 10, in test_logger
    a = 1 / 0
        ~~^~~
ZeroDivisionError: division by zero
[2023-08-21 18:55:29,578] (app.error) [ERROR] [197]: dddd
NoneType: None
[2023-08-21 18:55:29,578] (app.error) [ERROR] [197]: division by zero
Traceback (most recent call last):
  File "D:\workspace\ph-utils\tests\logger_utils.py", line 11, in test_logger
    a = 1 / 0
        ~~^~~
ZeroDivisionError: division by zero
[2023-08-21 18:57:20,759] (app.error) [ERROR] [197]: dddd
NoneType: None
Stack (most recent call last):
  File "D:\workspace\ph-utils\tests\logger_utils.py", line 12, in <module>
    test_logger()
  File "D:\workspace\ph-utils\tests\logger_utils.py", line 9, in test_logger
    log(exception=Exception("dddd"), name="NAME", prefix="params")
  File "D:\workspace\ph-utils\src\ph_utils\logger_utils.py", line 197, in log
    logging.getLogger("app.error").exception(except_error, stack_info=True)
[2023-08-21 18:57:37,590] (app.error) [ERROR] [197]: dddd
NoneType: None
Stack (most recent call last):
  File "D:\workspace\ph-utils\tests\logger_utils.py", line 16, in <module>
    test_logger()
  File "D:\workspace\ph-utils\tests\logger_utils.py", line 9, in test_logger
    log(exception=Exception("dddd"), name="NAME", prefix="params")
  File "D:\workspace\ph-utils\src\ph_utils\logger_utils.py", line 197, in log
    logging.getLogger("app.error").exception(except_error, stack_info=True)
[2023-08-21 18:57:37,591] (app.error) [ERROR] [197]: division by zero
Traceback (most recent call last):
  File "D:\workspace\ph-utils\tests\logger_utils.py", line 11, in test_logger
    a = 1 / 0
        ~~^~~
ZeroDivisionError: division by zero
Stack (most recent call last):
  File "D:\workspace\ph-utils\tests\logger_utils.py", line 16, in <module>
    test_logger()
  File "D:\workspace\ph-utils\tests\logger_utils.py", line 13, in test_logger
    log(exception=err, name="NAME", prefix="params")
  File "D:\workspace\ph-utils\src\ph_utils\logger_utils.py", line 197, in log
    logging.getLogger("app.error").exception(except_error, stack_info=True)
[2023-08-21 18:59:36,517] (app.error) [ERROR] [197]: dddd
NoneType: None
[2023-08-21 18:59:36,517] (app.error) [ERROR] [197]: division by zero
Traceback (most recent call last):
  File "D:\workspace\ph-utils\tests\logger_utils.py", line 11, in test_logger
    a = 1 / 0
        ~~^~~
ZeroDivisionError: division by zero
[2023-08-21 19:01:04,591] (app.error) [ERROR] [198]: dddd
NoneType: None
[2023-08-21 19:01:04,592] (app.error) [ERROR] [198]: division by zero
Traceback (most recent call last):
  File "D:\workspace\ph-utils\tests\logger_utils.py", line 11, in test_logger
    a = 1 / 0
        ~~^~~
ZeroDivisionError: division by zero
[2023-08-21 19:06:03,153] (app.error) [ERROR] [200]: dddd
NoneType: None
[2023-08-21 19:06:03,154] (app.error) [ERROR] [200]: division by zero
Traceback (most recent call last):
  File "D:\workspace\ph-utils\tests\logger_utils.py", line 11, in test_logger
    a = 1 / 0
        ~~^~~
ZeroDivisionError: division by zero
[2023-08-21 19:06:55,205] (app.error) [ERROR] [1593]: dddd
NoneType: None
[2023-08-21 19:06:55,205] (app.error) [ERROR] [1593]: division by zero
Traceback (most recent call last):
  File "D:\workspace\ph-utils\tests\logger_utils.py", line 11, in test_logger
    a = 1 / 0
        ~~^~~
ZeroDivisionError: division by zero
[2023-08-21 19:07:05,558] (app.error) [ERROR] [9]: dddd
NoneType: None
[2023-08-21 19:07:05,559] (app.error) [ERROR] [13]: division by zero
Traceback (most recent call last):
  File "D:\workspace\ph-utils\tests\logger_utils.py", line 11, in test_logger
    a = 1 / 0
        ~~^~~
ZeroDivisionError: division by zero
[2023-08-21 19:07:23,708] (app.error) [ERROR] [200]: dddd
NoneType: None
[2023-08-21 19:07:23,708] (app.error) [ERROR] [200]: division by zero
Traceback (most recent call last):
  File "D:\workspace\ph-utils\tests\logger_utils.py", line 11, in test_logger
    a = 1 / 0
        ~~^~~
ZeroDivisionError: division by zero
[2023-08-21 19:08:50,626] (app.error) [ERROR] [201]: dddd
NoneType: None
[2023-08-21 19:08:50,627] (app.error) [ERROR] [201]: division by zero
Traceback (most recent call last):
  File "D:\workspace\ph-utils\tests\logger_utils.py", line 11, in test_logger
    a = 1 / 0
        ~~^~~
ZeroDivisionError: division by zero
[2023-08-21 19:09:41,696] (app.error) [ERROR] [201]: dddd
NoneType: None
Stack (most recent call last):
  File "D:\workspace\ph-utils\tests\logger_utils.py", line 16, in <module>
    test_logger()
  File "D:\workspace\ph-utils\tests\logger_utils.py", line 9, in test_logger
    log(exception=Exception("dddd"), name="NAME", prefix="params")
  File "D:\workspace\ph-utils\src\ph_utils\logger_utils.py", line 201, in log
    logging.getLogger("app.error").exception(except_error, stack_info=True)
[2023-08-21 19:09:41,697] (app.error) [ERROR] [201]: division by zero
Traceback (most recent call last):
  File "D:\workspace\ph-utils\tests\logger_utils.py", line 11, in test_logger
    a = 1 / 0
        ~~^~~
ZeroDivisionError: division by zero
Stack (most recent call last):
  File "D:\workspace\ph-utils\tests\logger_utils.py", line 16, in <module>
    test_logger()
  File "D:\workspace\ph-utils\tests\logger_utils.py", line 13, in test_logger
    log(exception=err, name="NAME", prefix="params")
  File "D:\workspace\ph-utils\src\ph_utils\logger_utils.py", line 201, in log
    logging.getLogger("app.error").exception(except_error, stack_info=True)
[2023-08-21 19:10:13,750] (app.error) [ERROR] [198]: dddd
NoneType: None
Stack (most recent call last):
  File "D:\workspace\ph-utils\tests\logger_utils.py", line 16, in <module>
    test_logger()
  File "D:\workspace\ph-utils\tests\logger_utils.py", line 9, in test_logger
    log(exception=Exception("dddd"), name="NAME", prefix="params")
  File "D:\workspace\ph-utils\src\ph_utils\logger_utils.py", line 198, in log
    logging.getLogger("app.error").exception(except_error, stack_info=True)
[2023-08-21 19:10:13,750] (app.error) [ERROR] [198]: division by zero
Traceback (most recent call last):
  File "D:\workspace\ph-utils\tests\logger_utils.py", line 11, in test_logger
    a = 1 / 0
        ~~^~~
ZeroDivisionError: division by zero
Stack (most recent call last):
  File "D:\workspace\ph-utils\tests\logger_utils.py", line 16, in <module>
    test_logger()
  File "D:\workspace\ph-utils\tests\logger_utils.py", line 13, in test_logger
    log(exception=err, name="NAME", prefix="params")
  File "D:\workspace\ph-utils\src\ph_utils\logger_utils.py", line 198, in log
    logging.getLogger("app.error").exception(except_error, stack_info=True)
[2023-08-21 19:14:24,709] (app.error) [ERROR] [198]: fdsafds
NoneType: None
[2023-08-21 19:15:13,829] (app.error) [ERROR] [198]: fdsafds
NoneType: None
